nohup: ignoring input
 * Serving Flask app "app" (lazy loading)
 * Environment: production
   WARNING: Do not use the development server in a production environment.
   Use a production WSGI server instead.
 * Debug mode: off
 * Running on http://0.0.0.0:5556/ (Press CTRL+C to quit)
nohup: ignoring input
 * Serving Flask app "app" (lazy loading)
 * Environment: production
   WARNING: Do not use the development server in a production environment.
   Use a production WSGI server instead.
 * Debug mode: off
 * Running on http://0.0.0.0:5556/ (Press CTRL+C to quit)
[2018-12-18 03:08:59,302] ERROR in app: Exception on /notes [GET]
Traceback (most recent call last):
  File "/root/py3env/lib/python3.6/site-packages/mysql/connector/network.py", line 509, in open_connection
    self.sock.connect(sockaddr)
ConnectionRefusedError: [Errno 111] Connection refused

During handling of the above exception, another exception occurred:

Traceback (most recent call last):
  File "/root/py3env/lib/python3.6/site-packages/flask/app.py", line 2292, in wsgi_app
    response = self.full_dispatch_request()
  File "/root/py3env/lib/python3.6/site-packages/flask/app.py", line 1815, in full_dispatch_request
    rv = self.handle_user_exception(e)
  File "/root/py3env/lib/python3.6/site-packages/flask_cors/extension.py", line 161, in wrapped_function
    return cors_after_request(app.make_response(f(*args, **kwargs)))
  File "/root/py3env/lib/python3.6/site-packages/flask/app.py", line 1718, in handle_user_exception
    reraise(exc_type, exc_value, tb)
  File "/root/py3env/lib/python3.6/site-packages/flask/_compat.py", line 35, in reraise
    raise value
  File "/root/py3env/lib/python3.6/site-packages/flask/app.py", line 1813, in full_dispatch_request
    rv = self.dispatch_request()
  File "/root/py3env/lib/python3.6/site-packages/flask/app.py", line 1799, in dispatch_request
    return self.view_functions[rule.endpoint](**req.view_args)
  File "app.py", line 23, in notes
    return query_notes(categoryId,pageSize,pageNum)
  File "/roger/flowpc3.0server/notes.py", line 27, in query_notes
    return run(callback)
  File "/roger/flowpc3.0server/dbEngine.py", line 5, in run
    conn = mysql.connector.connect(port='6033',user='root', password='!@as56210', database='flowpc3.0', use_unicode=True)
  File "/root/py3env/lib/python3.6/site-packages/mysql/connector/__init__.py", line 179, in connect
    return MySQLConnection(*args, **kwargs)
  File "/root/py3env/lib/python3.6/site-packages/mysql/connector/connection.py", line 94, in __init__
    self.connect(**kwargs)
  File "/root/py3env/lib/python3.6/site-packages/mysql/connector/abstracts.py", line 722, in connect
    self._open_connection()
  File "/root/py3env/lib/python3.6/site-packages/mysql/connector/connection.py", line 207, in _open_connection
    self._socket.open_connection()
  File "/root/py3env/lib/python3.6/site-packages/mysql/connector/network.py", line 512, in open_connection
    errno=2003, values=(self.get_address(), _strioerror(err)))
mysql.connector.errors.InterfaceError: 2003: Can't connect to MySQL server on '127.0.0.1:6033' (111 Connection refused)
172.17.0.1 - - [18/Dec/2018 03:08:59] "GET /notes HTTP/1.1" 500 -
172.17.0.1 - - [18/Dec/2018 03:08:59] "GET /favicon.ico HTTP/1.1" 404 -
